 * Running on all addresses.
   WARNING: This is a development server. Do not use it in a production deployment.
 * Running on http://172.18.0.2:4444/ (Press CTRL+C to quit)
127.0.0.1 - - [02/Jan/2025 08:34:11] "GET /hi HTTP/1.1" 200 -
127.0.0.1 - - [02/Jan/2025 08:34:42] "GET /hi HTTP/1.1" 200 -
127.0.0.1 - - [02/Jan/2025 08:35:13] "GET /hi HTTP/1.1" 200 -
127.0.0.1 - - [02/Jan/2025 08:35:43] "GET /hi HTTP/1.1" 200 -
Exception on /hi [GET]
Traceback (most recent call last):
  File "/usr/local/lib/python3.6/dist-packages/urllib3/connection.py", line 170, in _new_conn
    (self._dns_host, self.port), self.timeout, **extra_kw
  File "/usr/local/lib/python3.6/dist-packages/urllib3/util/connection.py", line 96, in create_connection
    raise err
  File "/usr/local/lib/python3.6/dist-packages/urllib3/util/connection.py", line 86, in create_connection
    sock.connect(sa)
ConnectionRefusedError: [Errno 111] Connection refused

During handling of the above exception, another exception occurred:

Traceback (most recent call last):
  File "/usr/local/lib/python3.6/dist-packages/urllib3/connectionpool.py", line 706, in urlopen
    chunked=chunked,
  File "/usr/local/lib/python3.6/dist-packages/urllib3/connectionpool.py", line 394, in _make_request
    conn.request(method, url, **httplib_request_kw)
  File "/usr/local/lib/python3.6/dist-packages/urllib3/connection.py", line 234, in request
    super(HTTPConnection, self).request(method, url, body=body, headers=headers)
  File "/usr/lib/python3.6/http/client.py", line 1281, in request
    self._send_request(method, url, body, headers, encode_chunked)
  File "/usr/lib/python3.6/http/client.py", line 1327, in _send_request
    self.endheaders(body, encode_chunked=encode_chunked)
  File "/usr/lib/python3.6/http/client.py", line 1276, in endheaders
    self._send_output(message_body, encode_chunked=encode_chunked)
  File "/usr/lib/python3.6/http/client.py", line 1042, in _send_output
    self.send(msg)
  File "/usr/lib/python3.6/http/client.py", line 980, in send
    self.connect()
  File "/usr/local/lib/python3.6/dist-packages/urllib3/connection.py", line 200, in connect
    conn = self._new_conn()
  File "/usr/local/lib/python3.6/dist-packages/urllib3/connection.py", line 182, in _new_conn
    self, "Failed to establish a new connection: %s" % e
urllib3.exceptions.NewConnectionError: <urllib3.connection.HTTPConnection object at 0x7f0ec015bc18>: Failed to establish a new connection: [Errno 111] Connection refused

During handling of the above exception, another exception occurred:

Traceback (most recent call last):
  File "/usr/local/lib/python3.6/dist-packages/requests/adapters.py", line 449, in send
    timeout=timeout
  File "/usr/local/lib/python3.6/dist-packages/urllib3/connectionpool.py", line 756, in urlopen
    method, url, error=e, _pool=self, _stacktrace=sys.exc_info()[2]
  File "/usr/local/lib/python3.6/dist-packages/urllib3/util/retry.py", line 573, in increment
    raise MaxRetryError(_pool, url, error or ResponseError(cause))
urllib3.exceptions.MaxRetryError: HTTPConnectionPool(host='222.201.187.51', port=3333): Max retries exceeded with url: //heartbeat?name=1_n4 (Caused by NewConnectionError('<urllib3.connection.HTTPConnection object at 0x7f0ec015bc18>: Failed to establish a new connection: [Errno 111] Connection refused',))

During handling of the above exception, another exception occurred:

Traceback (most recent call last):
  File "/usr/local/lib/python3.6/dist-packages/flask/app.py", line 2073, in wsgi_app
    response = self.full_dispatch_request()
  File "/usr/local/lib/python3.6/dist-packages/flask/app.py", line 1518, in full_dispatch_request
    rv = self.handle_user_exception(e)
  File "/usr/local/lib/python3.6/dist-packages/flask/app.py", line 1516, in full_dispatch_request
    rv = self.dispatch_request()
  File "/usr/local/lib/python3.6/dist-packages/flask/app.py", line 1502, in dispatch_request
    return self.ensure_sync(self.view_functions[rule.endpoint])(**req.view_args)
  File "gl_peer.py", line 53, in route_hi
    worker_utils.heartbeat (agent_addr, node_name)
  File "/home/qianguo/worker/dml_app/1/worker_utils.py", line 38, in heartbeat
    send_data ('GET', path, agent_address)
  File "/home/qianguo/worker/dml_app/1/worker_utils.py", line 22, in send_data
    res = requests.get ('http://' + address + '/' + path)
  File "/usr/local/lib/python3.6/dist-packages/requests/api.py", line 76, in get
    return request('get', url, params=params, **kwargs)
  File "/usr/local/lib/python3.6/dist-packages/requests/api.py", line 61, in request
    return session.request(method=method, url=url, **kwargs)
  File "/usr/local/lib/python3.6/dist-packages/requests/sessions.py", line 542, in request
    resp = self.send(prep, **send_kwargs)
  File "/usr/local/lib/python3.6/dist-packages/requests/sessions.py", line 655, in send
    r = adapter.send(request, **kwargs)
  File "/usr/local/lib/python3.6/dist-packages/requests/adapters.py", line 516, in send
    raise ConnectionError(e, request=request)
requests.exceptions.ConnectionError: HTTPConnectionPool(host='222.201.187.51', port=3333): Max retries exceeded with url: //heartbeat?name=1_n4 (Caused by NewConnectionError('<urllib3.connection.HTTPConnection object at 0x7f0ec015bc18>: Failed to establish a new connection: [Errno 111] Connection refused',))
127.0.0.1 - - [02/Jan/2025 08:36:14] "[35m[1mGET /hi HTTP/1.1[0m" 500 -
Exception on /hi [GET]
Traceback (most recent call last):
  File "/usr/local/lib/python3.6/dist-packages/urllib3/connection.py", line 170, in _new_conn
    (self._dns_host, self.port), self.timeout, **extra_kw
  File "/usr/local/lib/python3.6/dist-packages/urllib3/util/connection.py", line 96, in create_connection
    raise err
  File "/usr/local/lib/python3.6/dist-packages/urllib3/util/connection.py", line 86, in create_connection
    sock.connect(sa)
ConnectionRefusedError: [Errno 111] Connection refused

During handling of the above exception, another exception occurred:

Traceback (most recent call last):
  File "/usr/local/lib/python3.6/dist-packages/urllib3/connectionpool.py", line 706, in urlopen
    chunked=chunked,
  File "/usr/local/lib/python3.6/dist-packages/urllib3/connectionpool.py", line 394, in _make_request
    conn.request(method, url, **httplib_request_kw)
  File "/usr/local/lib/python3.6/dist-packages/urllib3/connection.py", line 234, in request
    super(HTTPConnection, self).request(method, url, body=body, headers=headers)
  File "/usr/lib/python3.6/http/client.py", line 1281, in request
    self._send_request(method, url, body, headers, encode_chunked)
  File "/usr/lib/python3.6/http/client.py", line 1327, in _send_request
    self.endheaders(body, encode_chunked=encode_chunked)
  File "/usr/lib/python3.6/http/client.py", line 1276, in endheaders
    self._send_output(message_body, encode_chunked=encode_chunked)
  File "/usr/lib/python3.6/http/client.py", line 1042, in _send_output
    self.send(msg)
  File "/usr/lib/python3.6/http/client.py", line 980, in send
    self.connect()
  File "/usr/local/lib/python3.6/dist-packages/urllib3/connection.py", line 200, in connect
    conn = self._new_conn()
  File "/usr/local/lib/python3.6/dist-packages/urllib3/connection.py", line 182, in _new_conn
    self, "Failed to establish a new connection: %s" % e
urllib3.exceptions.NewConnectionError: <urllib3.connection.HTTPConnection object at 0x7f0ec00a3080>: Failed to establish a new connection: [Errno 111] Connection refused

During handling of the above exception, another exception occurred:

Traceback (most recent call last):
  File "/usr/local/lib/python3.6/dist-packages/requests/adapters.py", line 449, in send
    timeout=timeout
  File "/usr/local/lib/python3.6/dist-packages/urllib3/connectionpool.py", line 756, in urlopen
    method, url, error=e, _pool=self, _stacktrace=sys.exc_info()[2]
  File "/usr/local/lib/python3.6/dist-packages/urllib3/util/retry.py", line 573, in increment
    raise MaxRetryError(_pool, url, error or ResponseError(cause))
urllib3.exceptions.MaxRetryError: HTTPConnectionPool(host='222.201.187.51', port=3333): Max retries exceeded with url: //heartbeat?name=1_n4 (Caused by NewConnectionError('<urllib3.connection.HTTPConnection object at 0x7f0ec00a3080>: Failed to establish a new connection: [Errno 111] Connection refused',))

During handling of the above exception, another exception occurred:

Traceback (most recent call last):
  File "/usr/local/lib/python3.6/dist-packages/flask/app.py", line 2073, in wsgi_app
    response = self.full_dispatch_request()
  File "/usr/local/lib/python3.6/dist-packages/flask/app.py", line 1518, in full_dispatch_request
    rv = self.handle_user_exception(e)
  File "/usr/local/lib/python3.6/dist-packages/flask/app.py", line 1516, in full_dispatch_request
    rv = self.dispatch_request()
  File "/usr/local/lib/python3.6/dist-packages/flask/app.py", line 1502, in dispatch_request
    return self.ensure_sync(self.view_functions[rule.endpoint])(**req.view_args)
  File "gl_peer.py", line 53, in route_hi
    worker_utils.heartbeat (agent_addr, node_name)
  File "/home/qianguo/worker/dml_app/1/worker_utils.py", line 38, in heartbeat
    send_data ('GET', path, agent_address)
  File "/home/qianguo/worker/dml_app/1/worker_utils.py", line 22, in send_data
    res = requests.get ('http://' + address + '/' + path)
  File "/usr/local/lib/python3.6/dist-packages/requests/api.py", line 76, in get
    return request('get', url, params=params, **kwargs)
  File "/usr/local/lib/python3.6/dist-packages/requests/api.py", line 61, in request
    return session.request(method=method, url=url, **kwargs)
  File "/usr/local/lib/python3.6/dist-packages/requests/sessions.py", line 542, in request
    resp = self.send(prep, **send_kwargs)
  File "/usr/local/lib/python3.6/dist-packages/requests/sessions.py", line 655, in send
    r = adapter.send(request, **kwargs)
  File "/usr/local/lib/python3.6/dist-packages/requests/adapters.py", line 516, in send
    raise ConnectionError(e, request=request)
requests.exceptions.ConnectionError: HTTPConnectionPool(host='222.201.187.51', port=3333): Max retries exceeded with url: //heartbeat?name=1_n4 (Caused by NewConnectionError('<urllib3.connection.HTTPConnection object at 0x7f0ec00a3080>: Failed to establish a new connection: [Errno 111] Connection refused',))
127.0.0.1 - - [02/Jan/2025 08:36:44] "[35m[1mGET /hi HTTP/1.1[0m" 500 -
127.0.0.1 - - [02/Jan/2025 08:37:33] "GET /hi HTTP/1.1" 200 -
127.0.0.1 - - [02/Jan/2025 08:38:09] "GET /hi HTTP/1.1" 200 -
